<?xml version="1.0" ?>
<robot name="youbot" xmlns:controller="http://playerstage.sourceforge.net/gazebo/xmlschema/#controller" xmlns:interface="http://playerstage.sourceforge.net/gazebo/xmlschema/#interface" xmlns:sensor="http://playerstage.sourceforge.net/gazebo/xmlschema/#sensor" xmlns:xacro="http://ros.org/wiki/xacro">
  <!-- The following included files set up definitions of parts of the robot body -->
  <!-- misc common stuff? -->
  <!-- youbot base -->
  <!-- youbot plate -->
  <!-- youbot arm -->
  <!-- youbot gripper -->
  <!-- generic simulator_gazebo plugins for starting mechanism control, ros time, ros battery -->
  <gazebo>
    <plugin filename="libgazebo_ros_controller_manager.so" name="gazebo_ros_controller_manager">
      <alwaysOn>true</alwaysOn>
      <updateRate>1000.0</updateRate>
    </plugin>
    <plugin filename="libgazebo_ros_power_monitor.so" name="gazebo_ros_power_monitor_controller">
      <alwaysOn>true</alwaysOn>
      <updateRate>1.0</updateRate>
      <timeout>5</timeout>
      <interface:audio name="power_monitor_dummy_interface"/>
      <powerStateTopic>power_state</powerStateTopic>
      <powerStateRate>10.0</powerStateRate>
      <fullChargeCapacity>87.78</fullChargeCapacity>
      <dischargeRate>-474</dischargeRate>
      <chargeRate>525</chargeRate>
      <dischargeVoltage>15.52</dischargeVoltage>
      <chargeVoltage>16.41</chargeVoltage>
    </plugin>
  </gazebo>

  <!-- materials for visualization -->
  <material name="Orange">
    <color rgba="1.0 0.4 0.0 1.0"/>
  </material>
  <material name="Grey">
    <color rgba="0.7 0.7 0.7 1.0"/>
  </material>
  <material name="DarkGrey">
    <color rgba="0.3 0.3 0.3 1.0"/>
  </material>
  <material name="White">
    <color rgba="1.0 1.0 1.0 1.0"/>
  </material>
  <material name="Black">
    <color rgba="0.0 0.0 0.0 1.0"/>
  </material>
  <material name="Red">
    <color rgba="1.0 0.0 0.0 1.0"/>
  </material>
  <material name="Green">
    <color rgba="0.0 1.0 0.0 1.0"/>
  </material>
  <!-- Now we can start using the macros included above to define the actual youbot -->
  <!-- The first use of a macro.  This one was defined in base.urdf.xacro above.
       A macro like this will expand to a set of link and joint definitions, and to additional
       Gazebo-related extensions (sensor plugins, etc).  The macro takes an argument, name, 
       that equals "base", and uses it to generate names for its component links and joints 
       (e.g., base_link).  The included origin block is also an argument to the macro.  By convention, 
       the origin block defines where the component is w.r.t its parent (in this case the parent 
       is the world frame). For more, see http://www.ros.org/wiki/xacro -->
  <!-- foot for arm-->
  <link name="base_footprint">
    <inertial>
      <mass value="0.1"/>
      <origin rpy="0 0 0" xyz="0 0 -0.05"/>
      <inertia ixx="1.0" ixy="0.0" ixz="0.0" iyy="1.0" iyz="0.0" izz="1.0"/>
    </inertial>
    <visual>
      <origin rpy="0 0 0" xyz="0 0 0"/>
      <geometry>
        <box size="0.001 0.001 0.001"/>
      </geometry>
      <material name="Red"/>
    </visual>
    <collision>
      <origin rpy="0 0 0" xyz="0 0 -0.05"/>
      <geometry>
        <box size="0.001 0.001 0.001"/>
      </geometry>
    </collision>
  </link>
  <joint name="base_footprint_joint" type="fixed">
    <origin rpy="0 0 0" xyz="0 0 0"/>
    <child link="base_link"/>
    <parent link="base_footprint"/>
  </joint>
  <link name="base_link">
    <inertial>
      <mass value="22.0"/>
      <origin xyz="0 0 0"/>
      <inertia ixx="5.652232699207" ixy="-0.009719934438" ixz="1.293988226423" iyy="5.669473158652" iyz="-0.007379583694" izz="3.683196351726"/>
    </inertial>
    <visual>
      <origin rpy="0 0 0" xyz="0 0 0"/>
      <geometry>
        <mesh filename="package://youbot_description/meshes/youbot_base/base.dae"/>
      </geometry>
      <material name="DarkGrey"/>
    </visual>
    <collision>
      <origin rpy="0 0 0" xyz="0 0 0"/>
      <geometry>
        <!--<box size="${base_size_x} ${base_size_y} ${base_size_z}" />-->
        <mesh filename="package://youbot_description/meshes/youbot_base/base_convex.dae"/>
      </geometry>
    </collision>
  </link>


  <!-- Arm Joint 0 and Link 0 -->
  <joint name="arm_joint_0" type="fixed">
    <origin rpy="0 0 0" xyz="0.123 0 0.056"/>
    <parent link="base_link"/>
    <child link="arm_link_0"/>
  </joint>
  
  <link name="arm_link_0">
    <inertial>
      <origin rpy="0 0 0" xyz="0 0 0"/>
      <mass value="0.845"/>
      <inertia ixx="0.01" ixy="0" ixz="0" iyy="0.01" iyz="0" izz="0.01"/>
    </inertial>
    <visual>
      <origin rpy="0 0 0" xyz="0 0 0"/>
      <geometry>
        <mesh filename="package://youbot_description/meshes/youbot_arm/arm0.dae"/>
      </geometry>
      <material name="DarkGrey"/>
    </visual>
    <collision>
      <origin rpy="0 0 0" xyz="0 0 0"/>
      <geometry>
        <mesh filename="package://youbot_description/meshes/youbot_arm/arm0_convex.dae"/>
      </geometry>
    </collision>
  </link>
  
  <!-- Arm Joint 1 and Link 1 -->
  <joint name="arm_joint_1" type="revolute">
    <origin rpy="0 0 2.94960643587" xyz="0.024 0 0.096"/>
    <parent link="arm_link_0"/>
    <child link="arm_link_1"/>
    <axis xyz="0 0 -1"/>
    <dynamics damping="1" friction="1"/>
    <limit effort="9.5" lower="0" upper="5.89921287174" velocity="1.57079632679"/>
    <safety_controller k_position="20" k_velocity="1.51197195937" soft_lower_limit="0.001" soft_upper_limit="5.89821287174"/>
  </joint>
  
  <link name="arm_link_1">
    <inertial>
      <mass value="2.412"/>
      <origin rpy="0 0 0" xyz="0.01489 0.00213 0.00213"/>
      <inertia ixx="0.003863" ixy="-0.000979" ixz="0.000000" iyy="0.006196" iyz="0.000000" izz="0.006369"/>
    </inertial>
    <visual>
      <origin rpy="0 0 0" xyz="0 0 0"/>
      <geometry>
        <mesh filename="package://youbot_description/meshes/youbot_arm/arm1.dae"/>
      </geometry>
    </visual>
    <collision>
      <origin rpy="0 0 0" xyz="0 0 0"/>
      <geometry>
        <mesh filename="package://youbot_description/meshes/youbot_arm/arm1_convex.dae"/>
      </geometry>
    </collision>
  </link>
  
  <!-- Arm Joint 2 and Link 2 -->
  <joint name="arm_joint_2" type="revolute">
    <origin rpy="0 -1.1344640138 0" xyz="0.033 0 0.019"/>
    <parent link="arm_link_1"/>
    <child link="arm_link_2"/>
    <axis xyz="0 1 0"/>
    <dynamics damping="1" friction="1"/>
    <limit effort="9.5" lower="0" upper="2.70526034059" velocity="1.57079632679"/>
    <safety_controller k_position="20" k_velocity="6.04788783749" soft_lower_limit="0.001" soft_upper_limit="2.70426034059"/>
  </joint>
  
  <link name="arm_link_2">
    <inertial>
      <mass value="1.155"/>
      <origin rpy="0 0 0" xyz="0.10453 0.0017 -0.00297"/>
      <inertia ixx="0.000823" ixy="0.000000" ixz="-0.000000" iyy="0.004447" iyz="0.000000" izz="0.004439"/>
    </inertial>
    <visual>
      <origin rpy="0 0 0" xyz="0 -0.032 0.078"/>
      <geometry>
        <mesh filename="package://youbot_description/meshes/youbot_arm/arm2.dae"/>
      </geometry>
      <material name="Orange"/>
    </visual>
    <collision>
      <origin rpy="0 0 0" xyz="0 -0.032 0.078"/>
      <geometry>
        <mesh filename="package://youbot_description/meshes/youbot_arm/arm2_convex.dae"/>
      </geometry>
    </collision>
  </link>
  
  <!-- Arm Joint 3 and Link 3 -->
  <joint name="arm_joint_3" type="revolute">
    <origin rpy="0 2.54818070791 0" xyz="0.000 0.000 0.155"/>
    <parent link="arm_link_2"/>
    <child link="arm_link_3"/>
    <axis xyz="0 1 0"/>
    <dynamics damping="1" friction="1"/>
    <limit effort="6.0" lower="-5.18362787842" upper="0" velocity="1.57079632679"/>
    <safety_controller k_position="20" k_velocity="50" soft_lower_limit="-5.18262787842" soft_upper_limit="-0.001"/>
  </joint>
  
  <link name="arm_link_3">
    <inertial>
      <mass value="0.934"/>
      <origin rpy="0 0 0" xyz="0.0001 0.0967 0.02107"/>
      <inertia ixx="0.002459" ixy="0.000000" ixz="0.000000" iyy="0.002571" iyz="-0.000000" izz="0.000535"/>
    </inertial>
    <visual>
      <origin rpy="0 0 0" xyz="0.000 0.028 0.079"/>
      <geometry>
        <mesh filename="package://youbot_description/meshes/youbot_arm/arm3.dae"/>
      </geometry>
      <material name="Orange"/>
    </visual>
    <collision>
      <origin rpy="0 0 0" xyz="0.000 0.028 0.079"/>
      <geometry>
        <mesh filename="package://youbot_description/meshes/youbot_arm/arm3_convex.dae"/>
      </geometry>
    </collision>
  </link>
  
  <!-- Arm Joint 4 and Link 4 -->
  <joint name="arm_joint_4" type="revolute">
    <origin rpy="0 -1.78896248329 0" xyz="0.000 0.000 0.135"/>
    <parent link="arm_link_3"/>
    <child link="arm_link_4"/>
    <axis xyz="0 1 0"/>
    <dynamics damping="1" friction="1"/>
    <limit effort="2.0" lower="0" upper="3.57792496659" velocity="1.57079632679"/>
    <safety_controller k_position="20" k_velocity="100" soft_lower_limit="0" soft_upper_limit="3.57692496659"/>
  </joint>
  
  <link name="arm_link_4">
    <inertial>
      <mass value="0.877"/>
      <origin rpy="0 0 0" xyz="0.00011 0.05103 -0.02319"/>
      <inertia ixx="0.000869" ixy="0.000000" ixz="-0.000000" iyy="0.001173" iyz="-0.000231" izz="0.001091"/>
    </inertial>
    <visual>
      <origin rpy="0 0 0" xyz="0 -0.010 0.029"/>
      <geometry>
        <mesh filename="package://youbot_description/meshes/youbot_arm/arm4.dae"/>
      </geometry>
      <material name="Orange"/>
    </visual>
    <collision>
      <origin rpy="0 0 0" xyz="0 -0.010 0.029"/>
      <geometry>
        <mesh filename="package://youbot_description/meshes/youbot_arm/arm4_convex.dae"/>
      </geometry>
    </collision>
  </link>

  <!-- Arm Joint 5 and Link 5 -->
  <joint name="arm_joint_5" type="revolute">
    <origin rpy="0 1.57079632679 0" xyz="0.000 0.000 0.063"/>
    <parent link="arm_link_4"/>
    <child link="arm_link_5"/>
    <axis xyz="0 1 0"/>
    <dynamics damping="1" friction="1"/>
    <limit effort="2.0" lower="-3.14159265359" upper="3.14159265359" velocity="1.57079632679"/>
    <safety_controller k_position="20" k_velocity="100" soft_lower_limit="-3.14159265359" soft_upper_limit="3.14159265359"/>
  </joint>
  
  <link name="arm_link_5">
    <inertial>
      <mass value="0.148"/>
      <origin rpy="0 0 0" xyz="0.000 0.000 0.059"/>
      <inertia ixx="0.000034" ixy="0.000000" ixz="0.000000" iyy="0.000253" iyz="0.000000" izz="0.000249"/>
    </inertial>
    <visual>
      <origin rpy="0 0 0" xyz="0.000 0.000 0.001"/>
      <geometry>
        <mesh filename="package://youbot_description/meshes/youbot_arm/arm5.dae"/>
      </geometry>
      <material name="Orange"/>
    </visual>
    <collision>
      <origin rpy="0 0 0" xyz="0.000 0.000 0.001"/>
      <geometry>
        <mesh filename="package://youbot_description/meshes/youbot_arm/arm5_convex.dae"/>
      </geometry>
    </collision>
  </link>

  <!-- Base Link -->
  <link name="base_link">
    <inertial>
      <mass value="0.0"/>
      <inertia ixx="0" ixy="0" ixz="0" iyy="0" iyz="0" izz="0"/>
    </inertial>
    <visual>
      <geometry>
        <sphere radius="0.05"/>
      </geometry>
    </visual>
    <collision>
      <geometry>
        <sphere radius="0.05"/>
      </geometry>
    </collision>
  </link>

  <!-- Gazebo Specific Settings -->
  <gazebo reference="arm_link_0">
    <material value="youbot/DarkGrey"/>
    <turnGravityOff>false</turnGravityOff>
  </gazebo>

</robot>
